2020-06-13 09:26:28.576663


Traceback (most recent call last):
  File "/opt/virtualenvs/python3/lib/python3.8/site-packages/discord/ext/commands/core.py", line 83, in wrapped
    ret = await coro(*args, **kwargs)
  File "/home/runner/RashDarkmagentaComputer/utility.py", line 16, in wrapper
    await func(self, ctx, *args, **kwargs)
  File "/home/runner/RashDarkmagentaComputer/manitou_commands.py", line 233, in end_reset
    raise AttributeError('Game not started')
AttributeError: Game not started

The above exception was the direct cause of the following exception:

Traceback (most recent call last):
  File "main.py", line 165, in report_error
    raise error
  File "/opt/virtualenvs/python3/lib/python3.8/site-packages/discord/ext/commands/bot.py", line 892, in invoke
    await ctx.command.invoke(ctx)
  File "/opt/virtualenvs/python3/lib/python3.8/site-packages/discord/ext/commands/core.py", line 797, in invoke
    await injected(*ctx.args, **ctx.kwargs)
  File "/opt/virtualenvs/python3/lib/python3.8/site-packages/discord/ext/commands/core.py", line 92, in wrapped
    raise CommandInvokeError(exc) from exc
discord.ext.commands.errors.CommandInvokeError: Command raised an exception: AttributeError: Game not started




================================================



